Workbook

Sheet สรุป
A1: สรุปปริมาณงาน บ้านชั้นเดียว 3 ห้องนอน (Blender v413)
A2: ตัวเลขทั้งหมดเป็นการคำนวณเบื้องต้นจากโมเดล ใช้ประกอบการประเมินราคา ไม่ใช่ปริมาณสั่งซื้อจริง
A4: รายการ | B4: ปริมาณ | C4: หน่วย | D4: หมายเหตุ
A5: อิฐบล็อก 7x19x39 ซม. (รวมเผื่อเสีย) | B5: =ผนังก่ออิฐ!$H$26 | C5: ก้อน | D5: ผนัง 21 ชิ้น สูง 3.0 ม. หักช่องเปิด
A6: พื้นที่ก่อผนังสุทธิ | B6: =ผนังก่ออิฐ!$G$25 | C6: ตร.ม.
A7: กระเบื้องพื้น 60x60 รวมทุกแห่ง (รวมเผื่อเสีย) | B7: =พื้นและกระเบื้อง!$E$10 | C7: แผ่น | D7: พื้นบ้าน ห้องน้ำ และบันไดทั้งสองชุด
A8: กระเบื้องผนังห้องน้ำ 30x60 (รวมเผื่อเสีย) | B8: =พื้นและกระเบื้อง!$E$27 | C8: แผ่น | D8: สูง 2.60 ม.
A9: พื้นที่หลังคาตามลาด (รวมหลังคาเพิง) | B9: =หลังคา!$D$9 | C9: ตร.ม. | D9: ความลาด 17.1° และ 5°
A10: แผ่นหลังคา PU ลอน 760 (ประมาณ รวมเผื่อเสีย) | B10: =หลังคา!$F$9 | C10: แผ่น | D10: ประมาณเบื้องต้น ต้องแยกแผ่นตามแบบจริง
A11: ประตู (รวมบานคู่หน้าบ้าน) | B11: ='ประตู-หน้าต่าง'!$B$13 | C11: บาน
A12: หน้าต่าง | B12: ='ประตู-หน้าต่าง'!$B$34 | C12: บาน
A13: เสา | B13: =เสาและคอนกรีต!D4 | C13: ต้น
A14: คอนกรีตเสา | B14: =เสาและคอนกรีต!E4 | C14: ลบ.ม.
A15: พื้นที่ทาสี TOA 21001 | B15: =สีทา!$D$10 | C15: ตร.ม. | D15: ผนัง 2 ด้าน คานรอบบ้าน เสา
A16: แก้ล่าสุด 13 ต.ค. 2569: หน้าต่าง W7 W8 W10 สูง 1.10 ม., ถอดก๊อกครัวนอก+C1, สวิตช์ห้องน้ำ 2 เป็น 2 ตัว, โคมห้อยโต๊ะ, ฝ้าลานเพิ่ม 2 โซน, เสาอากาศทีวี UHF | 15 ต.ค. 2569: ไฟหลุมลานหน้า 6 ดวง + ฝ้าลอนลายไม้ลานหน้า (ยาวถึงห้องนอน 1), ไฟผนังกล่องดำข้างประตูหลัก 2 ดวง, สวิตช์ 3 ปุ่ม 2 ทางหน้าบ้าน, ถอดช่องลมจั่ว 4 ช่อง
A17: ค่าสมมติและที่มาอยู่ในชีต "ข้อสมมติ" (แก้ได้ที่ช่องสีน้ำเงิน ตัวเลขทั้งหมดจะเปลี่ยนตาม)
A18: จุดติดตั้งอุปกรณ์ไฟฟ้า (เต้ารับ/สวิตช์/กล่อง) | B18: =ไฟฟ้า!B12 | C18: จุด
A19: ท่อน้ำดี+น้ำทิ้ง+โสโครก (รวมเผื่อ) | B19: =SUMIF('ประปา-สุขาภิบาล'!A4:A12,"ท่อ*",'ประปา-สุขาภิบาล'!D4:D12) | C19: ม.
A20: ฝ้าเพดานรวม (ในบ้าน + ฝ้าลอนลายไม้ลานหน้า + ลาน 2 โซน) | B20: =ฝ้าเพดาน!B8 | C20: ตร.ม.
A21: ปูนซีเมนต์ ก่อ+ฉาบ+ทับหลัง (ผสมเอง รวมเผื่อ 5%) | B21: ='ปูนก่อ-ฉาบ-ทับหลัง'!C70 | C21: ถุง
A22: ทรายก่อ-ฉาบ-ทับหลัง (รวมเผื่อ 5%) | B22: ='ปูนก่อ-ฉาบ-ทับหลัง'!C71 | C22: ลบ.ม.
A23: คอนกรีตเอ็นทับหลัง | B23: ='ปูนก่อ-ฉาบ-ทับหลัง'!B53 | C23: ลบ.ม.

Sheet สรุปราคา
A1: สรุปราคาวัสดุโดยประมาณ (กรอกราคาต่อหน่วยเอง)
A2: กรอกเฉพาะช่องสีเหลือง "ราคาต่อหน่วย" ยอดรวมจะคำนวณให้ จำนวนดึงมาจากชีตต่าง ๆ โดยอัตโนมัติ รายการที่ไม่มีจำนวน (เหมา) ให้กรอกจำนวนเอง ราคายังไม่รวมค่าแรง ค่าขนส่ง และ VAT เว้นแต่กรอกในช่องด้านล่าง
B3: หมวด | G3: ยอดรวม (บาท)
B4: ผนังก่ออิฐ | G4: =SUMIF($B$22:$B$120,B4,$G$22:$G$120)
B5: ปูนก่อ-ฉาบ-ทับหลัง | G5: =SUMIF($B$22:$B$120,B5,$G$22:$G$120)
B6: พื้นและกระเบื้อง | G6: =SUMIF($B$22:$B$120,B6,$G$22:$G$120)
B7: หลังคา | G7: =SUMIF($B$22:$B$120,B7,$G$22:$G$120)
B8: ประตู-หน้าต่าง | G8: =SUMIF($B$22:$B$120,B8,$G$22:$G$120)
B9: Sheet1 | G9: =SUMIF($B$22:$B$120,B9,$G$22:$G$120)
B10: เสาและคอนกรีต | G10: =SUMIF($B$22:$B$120,B10,$G$22:$G$120)
B11: สีทา | G11: =SUMIF($B$22:$B$120,B11,$G$22:$G$120)
B12: ไฟฟ้า | G12: =SUMIF($B$22:$B$120,B12,$G$22:$G$120)
B13: ประปา-สุขาภิบาล | G13: =SUMIF($B$22:$B$120,B13,$G$22:$G$120)
B14: ฝ้าเพดาน | G14: =SUMIF($B$22:$B$120,B14,$G$22:$G$120)
B15: สุขภัณฑ์-ครัว | G15: =SUMIF($B$22:$B$120,B15,$G$22:$G$120)
B16: รวมค่าวัสดุตามรายการ | G16: =SUM(G4:G15)
B17: ค่าขนส่ง/เบ็ดเตล็ด (% ของค่าวัสดุ) | F17: 0 | G17: =G16*F17
B18: ภาษีมูลค่าเพิ่ม (ใส่ 7% ถ้าราคาที่กรอกยังไม่รวม VAT) | F18: 0 | G18: =(G16+G17)*F18
B19: รวมทั้งสิ้น (โดยประมาณ) | G19: =G16+G17+G18
A21: ลำดับ | B21: หมวด | C21: รายการ | D21: จำนวน | E21: หน่วย | F21: ราคาต่อหน่วย (บาท) | G21: รวม (บาท) | H21: หมายเหตุ
A22: 1 | B22: ผนังก่ออิฐ | C22: ='ผนังก่ออิฐ'!A33 | D22: ='ผนังก่ออิฐ'!B33 | E22: ='ผนังก่ออิฐ'!C33 | F22: 6.5 | G22: =IF(OR(D22="",F22=""),0,D22*F22) | H22: =IF('ผนังก่ออิฐ'!D33="","",'ผนังก่ออิฐ'!D33)
A23: 2 | B23: ปูนก่อ-ฉาบ-ทับหลัง | C23: ='ปูนก่อ-ฉาบ-ทับหลัง'!A86 | D23: ='ปูนก่อ-ฉาบ-ทับหลัง'!B86 | E23: ='ปูนก่อ-ฉาบ-ทับหลัง'!C86 | F23: 120 | G23: =IF(OR(D23="",F23=""),0,D23*F23) | H23: =IF('ปูนก่อ-ฉาบ-ทับหลัง'!D86="","",'ปูนก่อ-ฉาบ-ทับหลัง'!D86)
A24: 3 | B24: ปูนก่อ-ฉาบ-ทับหลัง | C24: ='ปูนก่อ-ฉาบ-ทับหลัง'!A87 | D24: ='ปูนก่อ-ฉาบ-ทับหลัง'!B87 | E24: ='ปูนก่อ-ฉาบ-ทับหลัง'!C87 | F24: 600 | G24: =IF(OR(D24="",F24=""),0,D24*F24) | H24: =IF('ปูนก่อ-ฉาบ-ทับหลัง'!D87="","",'ปูนก่อ-ฉาบ-ทับหลัง'!D87)
A25: 4 | B25: ปูนก่อ-ฉาบ-ทับหลัง | C25: ='ปูนก่อ-ฉาบ-ทับหลัง'!A88 | D25: ='ปูนก่อ-ฉาบ-ทับหลัง'!B88 | E25: ='ปูนก่อ-ฉาบ-ทับหลัง'!C88 | F25: 800 | G25: =IF(OR(D25="",F25=""),0,D25*F25) | H25: =IF('ปูนก่อ-ฉาบ-ทับหลัง'!D88="","",'ปูนก่อ-ฉาบ-ทับหลัง'!D88)
A26: 5 | B26: ปูนก่อ-ฉาบ-ทับหลัง | C26: ='ปูนก่อ-ฉาบ-ทับหลัง'!A89 | D26: ='ปูนก่อ-ฉาบ-ทับหลัง'!B89 | E26: ='ปูนก่อ-ฉาบ-ทับหลัง'!C89 | F26: 119.18 | G26: =IF(OR(D26="",F26=""),0,D26*F26) | H26: =IF('ปูนก่อ-ฉาบ-ทับหลัง'!D89="","",'ปูนก่อ-ฉาบ-ทับหลัง'!D89)
A27: 6 | B27: ปูนก่อ-ฉาบ-ทับหลัง | C27: ='ปูนก่อ-ฉาบ-ทับหลัง'!A90 | D27: ='ปูนก่อ-ฉาบ-ทับหลัง'!B90 | E27: ='ปูนก่อ-ฉาบ-ทับหลัง'!C90 | F27: 47.51 | G27: =IF(OR(D27="",F27=""),0,D27*F27) | H27: =IF('ปูนก่อ-ฉาบ-ทับหลัง'!D90="","",'ปูนก่อ-ฉาบ-ทับหลัง'!D90)
A28: 7 | B28: ปูนก่อ-ฉาบ-ทับหลัง | C28: ='ปูนก่อ-ฉาบ-ทับหลัง'!A91 | D28: ='ปูนก่อ-ฉาบ-ทับหลัง'!B91 | E28: ='ปูนก่อ-ฉาบ-ทับหลัง'!C91 | G28: =IF(OR(D28="",F28=""),0,D28*F28) | H28: =IF('ปูนก่อ-ฉาบ-ทับหลัง'!D91="","",'ปูนก่อ-ฉาบ-ทับหลัง'!D91)
A29: 8 | B29: พื้นและกระเบื้อง | C29: ='พื้นและกระเบื้อง'!A38 | D29: ='พื้นและกระเบื้อง'!B38 | E29: ='พื้นและกระเบื้อง'!C38 | F29: 250 | G29: =IF(OR(D29="",F29=""),0,D29*F29) | H29: =IF('พื้นและกระเบื้อง'!D38="","",'พื้นและกระเบื้อง'!D38)
A30: 9 | B30: พื้นและกระเบื้อง | C30: ='พื้นและกระเบื้อง'!A39 | D30: ='พื้นและกระเบื้อง'!B39 | E30: ='พื้นและกระเบื้อง'!C39 | F30: 250 | G30: =IF(OR(D30="",F30=""),0,D30*F30) | H30: =IF('พื้นและกระเบื้อง'!D39="","",'พื้นและกระเบื้อง'!D39)
A31: 10 | B31: พื้นและกระเบื้อง | C31: ='พื้นและกระเบื้อง'!A40 | D31: ='พื้นและกระเบื้อง'!B40 | E31: ='พื้นและกระเบื้อง'!C40 | F31: 250 | G31: =IF(OR(D31="",F31=""),0,D31*F31) | H31: =IF('พื้นและกระเบื้อง'!D40="","",'พื้นและกระเบื้อง'!D40)
A32: 11 | B32: พื้นและกระเบื้อง | C32: ='พื้นและกระเบื้อง'!A41 | D32: ='พื้นและกระเบื้อง'!B41 | E32: ='พื้นและกระเบื้อง'!C41 | F32: 161 | G32: =IF(OR(D32="",F32=""),0,D32*F32) | H32: =IF('พื้นและกระเบื้อง'!D41="","",'พื้นและกระเบื้อง'!D41)
A33: 12 | B33: พื้นและกระเบื้อง | C33: ='พื้นและกระเบื้อง'!A42 | D33: ='พื้นและกระเบื้อง'!B42 | E33: ='พื้นและกระเบื้อง'!C42 | F33: 220 | G33: =IF(OR(D33="",F33=""),0,D33*F33) | H33: =IF('พื้นและกระเบื้อง'!D42="","",'พื้นและกระเบื้อง'!D42)
A34: 13 | B34: พื้นและกระเบื้อง | C34: ='พื้นและกระเบื้อง'!A43 | D34: ='พื้นและกระเบื้อง'!B43 | E34: ='พื้นและกระเบื้อง'!C43 | G34: =IF(OR(D34="",F34=""),0,D34*F34) | H34: =IF('พื้นและกระเบื้อง'!D43="","",'พื้นและกระเบื้อง'!D43)
A35: 14 | B35: หลังคา | C35: ='หลังคา'!A17 | D35: ='หลังคา'!B17 | E35: ='หลังคา'!C17 | F35: 106000 | G35: =IF(OR(D35="",F35=""),0,D35*F35) | H35: =IF('หลังคา'!D17="","",'หลังคา'!D17)
A36: 15 | B36: หลังคา | C36: ='หลังคา'!A18 | D36: ='หลังคา'!B18 | E36: ='หลังคา'!C18 | F36: 2 | G36: =IF(OR(D36="",F36=""),0,D36*F36) | H36: =IF('หลังคา'!D18="","",'หลังคา'!D18)
A37: 16 | B37: หลังคา | C37: ='หลังคา'!A19 | E37: ='หลังคา'!C19 | G37: =IF(OR(D37="",F37=""),0,D37*F37) | H37: =IF('หลังคา'!D19="","",'หลังคา'!D19)
A38: 17 | B38: หลังคา | C38: ='หลังคา'!A20 | E38: ='หลังคา'!C20 | G38: =IF(OR(D38="",F38=""),0,D38*F38) | H38: =IF('หลังคา'!D20="","",'หลังคา'!D20)
A39: 18 | B39: ประตู-หน้าต่าง | C39: ='ประตู-หน้าต่าง'!A41 | D39: ='ประตู-หน้าต่าง'!B41 | E39: ='ประตู-หน้าต่าง'!C41 | F39: 2890 | G39: =IF(OR(D39="",F39=""),0,D39*F39) | H39: =IF('ประตู-หน้าต่าง'!D41="","",'ประตู-หน้าต่าง'!D41)
A40: 19 | B40: ประตู-หน้าต่าง | C40: ='ประตู-หน้าต่าง'!A42 | D40: ='ประตู-หน้าต่าง'!B42 | E40: ='ประตู-หน้าต่าง'!C42 | F40: 550 | G40: =IF(OR(D40="",F40=""),0,D40*F40) | H40: =IF('ประตู-หน้าต่าง'!D42="","",'ประตู-หน้าต่าง'!D42)
A41: 20 | B41: ประตู-หน้าต่าง | C41: ='ประตู-หน้าต่าง'!A43 | D41: ='ประตู-หน้าต่าง'!B43 | E41: ='ประตู-หน้าต่าง'!C43 | F41: 2750 | G41: =IF(OR(D41="",F41=""),0,D41*F41) | H41: =IF('ประตู-หน้าต่าง'!D43="","",'ประตู-หน้าต่าง'!D43)
...

Sheet ข้อสมมติ
A1: ข้อสมมติและค่าที่ใช้คำนวณ (แก้ได้เฉพาะช่องสีน้ำเงิน พื้นเหลือง)
A3: รายการ | B3: ค่า | C3: หมายเหตุ / ที่มา
A4: จำนวนอิฐบล็อกต่อ ตร.ม. (บล็อก 7x19x39 ซม. รวมร่องปูน) | B4: 12.5 | C4: ค่ามาตรฐานทั่วไป ไม่ใช่ค่าจากแบบ - ขนาดอิฐอื่นต้องเปลี่ยนค่านี้
A5: เผื่อเสียอิฐบล็อก | B5: 0.05 | C5: สมมติ 5%
A6: กระเบื้องพื้น แกรนิตโต้ ด้านละ (ม.) | B6: 0.6 | C6: ตามที่ผู้ใช้กำหนด 60x60 ซม.
A7: เผื่อเสียกระเบื้องพื้น | B7: 0.1 | C7: สมมติ 10% (เศษตัดและแตกหัก)
A8: กระเบื้องผนังห้องน้ำ แผ่นละ (ตร.ม.) 30x60 ซม. | B8: 0.18 | C8: ขนาดตามลายในโมเดล (30x60 ซม.) ผู้ใช้ไม่ได้ระบุขนาดจริง
A9: เผื่อเสียกระเบื้องผนัง | B9: 0.1 | C9: สมมติ 10%
A10: ความกว้างหน้าตัดแผ่น PU ลอน 760 (ม.) | B10: 0.76 | C10: ตามที่ผู้ใช้กำหนด
A11: เผื่อเสียแผ่นหลังคา | B11: 0.1 | C11: สมมติ 10% (ตัดมุมสันหยา/ร่อง)
A12: ความลาดหลังคาจั่ว (องศา) | B12: 17.1 | C12: จากโมเดล a, b, c, d
A13: ความลาดหลังคาเพิง (องศา) | B13: 5 | C13: วัดจากโมเดล merged-roof.001
A14: ความหนาพื้นคอนกรีต (ม.) | B14: 0.5 | C14: จากโมเดล (พื้นสูง 0.5 ม. จากระดับดิน 0.0)
A15: ความสูงกระเบื้องผนังห้องน้ำ จากพื้นกระเบื้อง (ม.) | B15: 2.588 | C15: โมเดล z 0.512 ถึง 3.10
A18: หมายเหตุ: ปริมาณทั้งหมดคำนวณจากโมเดล Blender v413 (ขนาดกรอบนอกของประตูหน้าต่าง) ยังไม่หักเสา คานทับหลัง และการซ้อนที่มุมผนัง ควรให้ผู้รับเหมาตรวจนับหน้างานอีกครั้ง

Sheet ผนังก่ออิฐ
A1: ปริมาณผนังก่ออิฐและอิฐบล็อก
A3: ผนัง | B3: ยาว (ม.) | C3: สูง (ม.) | D3: หนา (ม.) | E3: พื้นที่รวม (ตร.ม.) | F3: หักช่องเปิด (ตร.ม.) | G3: พื้นที่ก่อสุทธิ (ตร.ม.) | H3: อิฐบล็อก (ก้อน)
A4: ผนังนอก_ตะวันตก_นอน1 | B4: 5.12 | C4: 3 | D4: 0.12 | E4: =B4*C4 | F4: 2.2 | G4: =E4-F4 | H4: =G4*ข้อสมมติ!$B$4
A5: ผนังนอก_ตะวันออก_นอน2 | B5: 5.06 | C5: 3 | D5: 0.12 | E5: =B5*C5 | F5: 2.2 | G5: =E5-F5 | H5: =G5*ข้อสมมติ!$B$4
A6: ผนังนอก_ตะวันออก_นั่งเล่น | B6: 3.56 | C6: 3 | D6: 0.12 | E6: =B6*C6 | F6: 3.6 | G6: =E6-F6 | H6: =G6*ข้อสมมติ!$B$4
A7: ผนังนอก_ตะวันออก_เก็บของ+นั่งเล่น | B7: 4.5 | C7: 3 | D7: 0.12 | E7: =B7*C7 | F7: 1.72 | G7: =E7-F7 | H7: =G7*ข้อสมมติ!$B$4
A8: ผนังนอก_เหนือ_นอน1+น้ำ1+น้ำ2+นอน2 | B8: 11.12 | C8: 3 | D8: 0.12 | E8: =B8*C8 | F8: 4.6 | G8: =E8-F8 | H8: =G8*ข้อสมมติ!$B$4
A9: ผนังนอก_เหนือ_นั่งเล่น | B9: 1.85 | C9: 3 | D9: 0.12 | E9: =B9*C9 | F9: 1.6 | G9: =E9-F9 | H9: =G9*ข้อสมมติ!$B$4
A10: ผนังนอก_ใต้_นอน1 | B10: 2.56 | C10: 3 | D10: 0.12 | E10: =B10*C10 | F10: 0.75 | G10: =E10-F10 | H10: =G10*ข้อสมมติ!$B$4
A11: ผนังนอก_ใต้_นั่งเล่น | B11: 5.62 | C11: 3 | D11: 0.12 | E11: =B11*C11 | F11: 1.5 | G11: =E11-F11 | H11: =G11*ข้อสมมติ!$B$4
A12: ผนังนอก_ใต้_เก็บของ | B12: 1.85 | C12: 3 | D12: 0.12 | E12: =B12*C12 | F12: 0.4 | G12: =E12-F12 | H12: =G12*ข้อสมมติ!$B$4
A13: ผนังใน_นอน1|นั่งเล่น | B13: 2.06 | C13: 3 | D13: 0.12 | E13: =B13*C13 | F13: 1.6 | G13: =E13-F13 | H13: =G13*ข้อสมมติ!$B$4
A14: ผนังใน_นอน1|น้ำ1_1 | B14: 3 | C14: 3 | D14: 0.12 | E14: =B14*C14 | F14: 0 | G14: =E14-F14 | H14: =G14*ข้อสมมติ!$B$4
A15: ผนังใน_นอน1|น้ำ1_2 | B15: 2.06 | C15: 3 | D15: 0.12 | E15: =B15*C15 | F15: 1.4 | G15: =E15-F15 | H15: =G15*ข้อสมมติ!$B$4
... A24: ผนังใน_เก็บของ|นั่งเล่น | B24: 1.85 | C24: 3 | D24: 0.12 | E24: =B24*C24 | F24: 1.4 | G24: =E24-F24 | H24: =G24*ข้อสมมติ!$B$4
A25: รวม | E25: =SUM(E4:E24) | F25: =SUM(F4:F24) | G25: =SUM(G4:G24) | H25: =SUM(H4:H24)
A26: รวมเผื่อเสีย | H26: =ROUNDUP(H25*(1+ข้อสมมติ!$B$5),0) | J26: =H26*6.5
A28: ช่องเปิดวัดจากกรอบนอกของประตูและหน้าต่างที่ติดกับผนังนั้น ความยาวผนังวัดจากกรอบ (อาจนับซ้อนที่มุม)
A31: สิ่งที่ต้องซื้อ (จากชีตนี้)
A32: รายการที่ต้องซื้อ | B32: จำนวน | C32: หน่วย | D32: หมายเหตุ
A33: อิฐบล็อก 7x19x39 ซม. (รวมเผื่อเสีย หลังหักทับหลัง) | B33: ='ปูนก่อ-ฉาบ-ทับหลัง'!B57 | C33: ก้อน | D33: ดึงจากชีต ปูนก่อ-ฉาบ-ทับหลัง
A35: ปูนก่อ/ปูนฉาบ/ทราย ดูรายการซื้อในชีต "ปูนก่อ-ฉาบ-ทับหลัง"

Sheet ปูนก่อ-ฉาบ-ทับหลัง
A1: สรุปปูนก่อ ปูนฉาบ และเอ็นทับหลัง (ผสมเอง)
A2: แก้ได้เฉพาะช่องสีน้ำเงินพื้นเหลือง ค่าสมมติทั้งหมดเป็นค่าทั่วไป ไม่ใช่ค่าจากวิศวกร (หน้าตัดทับหลัง เหล็กเสริม สูตรคอนกรีต ต้องให้วิศวกรยืนยัน)
A4: ข้อสมมติ | B4: ค่า | E4: หมายเหตุ
A5: ความยาวทับหลังเข้าผนังแต่ละข้าง (ม.) | B5: 0.2 | E5: ค่าทั่วไป 15–20 ซม.
A6: ความกว้างทับหลัง (ม.) | B6: 0.12 | E6: เท่าความหนาผนังในโมเดล
A7: ความสูงทับหลัง (ม.) | B7: 0.15 | E7: ค่าสมมติ
A8: ปูนก่อสุทธิ (ลบ.ม./ตร.ม. ผนัง) | B8: 0.00516 | E8: บล็อก 7x19x39 รอยต่อ 1 ซม. (คำนวณ 5 ชั้น/ม. + 12.5 ก้อน/ตร.ม.)
A9: เผื่อสูญเสียปูนก่อ | B9: 1.25 | E9: x1.25
A10: ความหนาปูนฉาบ (ม.) | B10: 0.015 | E10: ฉาบ 1.5 ซม. ต่อด้าน
A11: เผื่อผิวไม่เรียบ/สูญเสียปูนฉาบ | B11: 1.2 | E11: x1.20
A12: ส่วนผสมแห้ง ÷ ปูนผสมแล้ว (ปูนก่อ/ฉาบ) | B12: 1.3 | E12: ปริมาตรทราย+ปูนแห้ง ต่อปูนผสมแล้ว 1 ลบ.ม.
A13: ส่วนผสมแห้ง ÷ คอนกรีต (1:2:4) | B13: 1.54 | E13: ค่าทั่วไป 1.50–1.57
A14: ความหนาแน่นปูนซีเมนต์ (กก./ลบ.ม.) | B14: 1440
A15: น้ำหนักปูนซีเมนต์ต่อถุง (กก.) | B15: 50
A16: ปูนก่อ: ส่วนปูนซีเมนต์ | B16: 1 | E16: 1 : 3
A17: ปูนก่อ: ส่วนทราย | B17: 3
A18: ปูนฉาบ: ส่วนปูนซีเมนต์ | B18: 1 | E18: 1 : 3 (ถ้า 1 : 4 ให้ใส่ทราย 4)
A19: ปูนฉาบ: ส่วนทราย | B19: 3
A20: คอนกรีตทับหลัง: ซีเมนต์ : ทราย : หิน | E20: 1 : 2 : 4 (ใส่ในสูตรด้านล่าง)
A21: เผื่อสั่งซื้อ (ปูน ทราย หิน) | B21: 0.05
A23: ช่องเปิด (รหัสตามพิมพ์เขียว A-09) | B23: กว้างช่องเปิด (ม.) | C23: ความยาวทับหลัง (ม.)
A24: D1 ประตูห้องน้ำ 2 ↔ ห้องนอน 2 | B24: 0.9 | C24: =B24+2*$B$5
A25: D2 ประตูห้องนอน 1 ↔ ห้องน้ำ 1 | B25: 0.7 | C25: =B25+2*$B$5
A26: D3 ประตูห้องนั่งเล่น ↔ ห้องน้ำ 2 | B26: 0.7 | C26: =B26+2*$B$5
A27: D4 ประตูห้องนอน 1 ↔ ห้องนั่งเล่น | B27: 0.8 | C27: =B27+2*$B$5
A28: D5 ประตูห้องนั่งเล่น ↔ ห้องนอน 2 | B28: 0.8 | C28: =B28+2*$B$5
A29: D6 ประตูหลังบ้าน | B29: 0.8 | C29: =B29+2*$B$5
A30: D7 ประตูหลักคู่ | B30: 2 | C30: =B30+2*$B$5
A31: D8 ประตูห้องเก็บของ | B31: 0.7 | C31: =B31+2*$B$5
A32: W1 หน้าต่างนอน 1 เหนือ | B32: 0.5 | C32: =B32+2*$B$5
A33: W2 หน้าต่างนอน 1 เหนือ | B33: 0.5 | C33: =B33+2*$B$5
A34: W3 หน้าต่างน้ำ 1 เหนือ | B34: 0.8 | C34: =B34+2*$B$5
A35: W4 หน้าต่างน้ำ 2 เหนือ | B35: 0.8 | C35: =B35+2*$B$5
... A47: W16 หน้าต่างนั่งเล่น ใต้ | B47: 0.5 | C47: =B47+2*$B$5
A48: รวมช่องเปิด / ความยาวทับหลัง | B48: =SUM(B24:B47) | C48: =SUM(C24:C47) | E48: =COUNTA(A24:A47)&" ช่อง"
A50: ปริมาณงาน | B50: ค่า | C50: หน่วย | E50: หมายเหตุ
A51: ความยาวทับหลังรวม | B51: =C48 | C51: ม.
A52: คอนกรีตทับหลัง (ก่อนเผื่อ) | B52: =B51*B6*B7 | C52: ลบ.ม. | E52: ยาว x กว้าง x สูง
A53: คอนกรีตทับหลัง (เผื่อสั่งซื้อ) | B53: =B52*(1+B21) | C53: ลบ.ม.
A54: พื้นที่ผิวหน้าทับหลังที่แทนอิฐ | B54: =B51*B7 | C54: ตร.ม.
...

Sheet พื้นและกระเบื้อง
A1: กระเบื้องพื้น ผนังห้องน้ำ และบันได
A3: รายการ | B3: กว้าง (ม.) | C3: สูง/ยาว (ม.) | D3: พื้นที่ (ตร.ม.) | E3: จำนวน (แผ่น)
A4: พื้นคอนกรีต ผิวบนทั้งหมด (รวมระเบียงและลานหน้าบ้าน) | D4: 132.262
A5: หัก พื้นห้องน้ำ 1 และ 2 (ปูกระเบื้องเทาอ่อนแยก) | B5: 1.88 | C5: 2.76 | D5: =2*B5*C5
A6: พื้นที่ปูกระเบื้องแกรนิตโต้ ครีมขาว 60x60 | D6: =D4-D5 | E6: =ROUNDUP(D6/(ข้อสมมติ!$B$6*ข้อสมมติ!$B$6)*(1+ข้อสมมติ!$B$7),0)
A7: กระเบื้องพื้นห้องน้ำ เทาอ่อน (60x60) 2 ห้อง | D7: =D5 | E7: =ROUNDUP(D7/(ข้อสมมติ!$B$6*ข้อสมมติ!$B$6)*(1+ข้อสมมติ!$B$7),0)
A8: กระเบื้องบันไดหน้าบ้าน (ขั้นนอนและขั้นตั้ง) | D8: 8.887 | E8: =ROUNDUP(D8/(ข้อสมมติ!$B$6*ข้อสมมติ!$B$6)*(1+ข้อสมมติ!$B$7),0)
A9: กระเบื้องลานและบันไดหลังบ้าน | D9: =3.2+2.096 | E9: =ROUNDUP(D9/(ข้อสมมติ!$B$6*ข้อสมมติ!$B$6)*(1+ข้อสมมติ!$B$7),0)
A10: รวมกระเบื้อง 60x60 (พื้นบ้าน + บันได + ห้องน้ำ) | D10: =D6+D7+D8+D9 | E10: =E6+E7+E8+E9
A12: กระเบื้องผนังห้องน้ำ (สูง 2.60 ม. จากพื้น เว้นช่องประตู/หน้าต่าง)
A13: ผนัง | B13: กว้าง (ม.) | C13: สูง (ม.) | D13: พื้นที่ (ตร.ม.)
A14: น้ำ1 เหนือ ใต้หน้าต่าง (ถึง z 2.22) | B14: 1.88 | C14: 1.708 | D14: =B14*C14
A15: น้ำ1 เหนือ ข้างหน้าต่าง (กว้าง 1.88-0.84) | B15: 1.04 | C15: 0.88 | D15: =B15*C15
A16: น้ำ1 ใต้ ข้างประตู (กว้าง 1.88-0.70) | B16: 1.18 | C16: =ข้อสมมติ!$B$15 | D16: =B16*C16
A17: น้ำ1 ใต้ เหนือกรอบประตู | B17: 0.7 | C17: 0.6 | D17: =B17*C17
A18: น้ำ1 ตะวันตก | B18: 2.76 | C18: =ข้อสมมติ!$B$15 | D18: =B18*C18
A19: น้ำ1 ตะวันออก (ผนังร่วมกับน้ำ2) | B19: 2.76 | C19: =ข้อสมมติ!$B$15 | D19: =B19*C19
A20: น้ำ2 เหนือ ใต้หน้าต่าง | B20: 1.88 | C20: 1.708 | D20: =B20*C20
A21: น้ำ2 เหนือ ข้างหน้าต่าง | B21: 1.04 | C21: 0.88 | D21: =B21*C21
A22: น้ำ2 ใต้ ข้างประตู | B22: 1.18 | C22: =ข้อสมมติ!$B$15 | D22: =B22*C22
A23: น้ำ2 ใต้ เหนือกรอบประตู | B23: 0.7 | C23: 0.6 | D23: =B23*C23
A24: น้ำ2 ตะวันตก (ผนังร่วมกับน้ำ1) | B24: 2.76 | C24: =ข้อสมมติ!$B$15 | D24: =B24*C24
A25: น้ำ2 ตะวันออก เหนือช่องประตู (ยาว 2.76-0.90) | B25: 1.86 | C25: =ข้อสมมติ!$B$15 | D25: =B25*C25
A26: น้ำ2 ตะวันออก เหนือกรอบประตู | B26: 0.9 | C26: 0.5 | D26: =B26*C26
A27: รวมกระเบื้องผนังห้องน้ำ (30x60) | D27: =SUM(D14:D26) | E27: =ROUNDUP(D27/ข้อสมมติ!$B$8*(1+ข้อสมมติ!$B$9),0)
A29: ไม่หักพื้นที่ใต้เคาน์เตอร์ตั้งอ่างและแถบหลังโถสุขภัณฑ์ ซึ่งก่อทับกระเบื้อง
A32: สิ่งที่ต้องซื้อ (จากชีตนี้)
A33: ปูนกาว (กก./ตร.ม.) | B33: 5 | D33: ค่าทั่วไป 4–6
A34: ขนาดถุงปูนกาว (กก.) | B34: 20
A35: ยาแนว (กก./ตร.ม.) | B35: 0.4
A36: ขนาดถุงยาแนว (กก.) | B36: 1
A37: รายการที่ต้องซื้อ | B37: จำนวน | C37: หน่วย | D37: หมายเหตุ
A38: กระเบื้องแกรนิตโต้ ครีมขาว 60x60 (พื้นบ้าน บันไดหน้าบ้าน ลาน/บันไดหลังบ้าน) | B38: =ROUNDUP((D6+D8+D9)*(1+ข้อสมมติ!$B$7),1) | C38: ตร.ม. | D38: ="รวมเผื่อเสีย "&TEXT(ข้อสมมติ!$B$7,"0%")&" (~"&TEXT(E6+E8+E9,"#,##0")&" แผ่น)"
A39: กระเบื้องพื้นห้องน้ำ เทาอ่อน 60x60 | B39: =ROUNDUP(D7*(1+ข้อสมมติ!$B$7),1) | C39: ตร.ม. | D39: ="รวมเผื่อเสีย "&TEXT(ข้อสมมติ!$B$7,"0%")&" (~"&TEXT(E7,"#,##0")&" แผ่น)"
A40: กระเบื้องผนังห้องน้ำ 30x60 | B40: =ROUNDUP(D27*(1+ข้อสมมติ!$B$9),1) | C40: ตร.ม. | D40: ="รวมเผื่อเสีย "&TEXT(ข้อสมมติ!$B$9,"0%")&" (~"&TEXT(E27,"#,##0")&" แผ่น)"
A41: ปูนกาวปูกระเบื้อง (ถุง 20 กก.) | B41: =ROUNDUP((D10+D27)*$B$33/$B$34,0) | C41: ถุง | D41: พื้นที่ปูพื้น+ผนัง
A42: ยาแนวกระเบื้อง (ถุง 1 กก.) | B42: =ROUNDUP((D10+D27)*$B$35/$B$36,0) | C42: ถุง
A43: วัสดุกันซึมพื้นห้องน้ำ (ตามพื้นที่ที่ผลิตภัณฑ์กำหนด) | B43: =D7 | C43: ตร.ม. | D43: พื้นที่พื้นห้องน้ำ 2 ห้อง ยังไม่รวมผนังสูง 30 ซม.

Sheet หลังคา
A1: หลังคา แผ่น PU ลอน 760
A3: ส่วนหลังคา | B3: พื้นที่ในแนวราบ (ตร.ม.) | C3: ความลาด (องศา) | D3: พื้นที่ตามลาด (ตร.ม.) | E3: ยาวตามลาดสูงสุด (ม.) | F3: ขนาดแผ่น (แผ่น) | G3: หมายเหตุ
A4: a (ปีกห้องนอน ด้านเหนือ) | B4: 39.48 | C4: =ข้อสมมติ!$B$12 | D4: =B4/COS(RADIANS(C4)) | E4: =3.56/COS(RADIANS(C4)) | F4: =ROUNDUP(D4*(1+ข้อสมมติ!$B$11)/(ข้อสมมติ!$B$10*E4),0) | G4: ประมาณจากพื้นที่ ÷ (0.76 × ยาวตามลาด)
A5: b (ปีกห้องนอน ด้านใต้) | B5: 26.82 | C5: =ข้อสมมติ!$B$12 | D5: =B5/COS(RADIANS(C5)) | E5: =3.56/COS(RADIANS(C5)) | F5: =ROUNDUP(D5*(1+ข้อสมมติ!$B$11)/(ข้อสมมติ!$B$10*E5),0) | G5: ประมาณจากพื้นที่ ÷ (0.76 × ยาวตามลาด)
A6: c (ปีกนั่งเล่น ด้านตะวันตก) | B6: 33.41 | C6: =ข้อสมมติ!$B$12 | D6: =B6/COS(RADIANS(C6)) | E6: =3.37/COS(RADIANS(C6)) | F6: =ROUNDUP(D6*(1+ข้อสมมติ!$B$11)/(ข้อสมมติ!$B$10*E6),0) | G6: ประมาณจากพื้นที่ ÷ (0.76 × ยาวตามลาด)
A7: d (ปีกนั่งเล่น ด้านตะวันออก) | B7: 70.98 | C7: =ข้อสมมติ!$B$12 | D7: =B7/COS(RADIANS(C7)) | E7: =5.1/COS(RADIANS(C7)) | F7: =ROUNDUP(D7*(1+ข้อสมมติ!$B$11)/(ข้อสมมติ!$B$10*E7),0) | G7: ประมาณจากพื้นที่ ÷ (0.76 × ยาวตามลาด)
A8: หลังคาเพิงลานหน้าบ้าน (x 1.33 ถึง 5.00, y -14.11 ถึง -5.56) | B8: 31.41 | C8: =ข้อสมมติ!$B$13 | D8: =B8/COS(RADIANS(C8)) | E8: =3.674/COS(RADIANS(C8)) | F8: =ROUNDUP(D8*(1+ข้อสมมติ!$B$11)/(ข้อสมมติ!$B$10*E8),0) | G8: ตัดเหลือซ้อนใต้หลังคา c แค่ 0.12 ม.
A9: รวมพื้นที่หลังคา | D9: =SUM(D4:D8) | F9: =SUM(F4:F8)
A11: จำนวนแผ่นเป็นค่าประมาณเบื้องต้น ต้องให้ผู้จัดทำหลังคาแยกแผ่นตามแบบจริง (ความยาวแผ่นแต่ละแผ่นต่างกันที่สันหยาและร่อง)
A14: สิ่งที่ต้องซื้อ (จากชีตนี้)
A15: สกรูต่อพื้นที่หลังคา (ตัว/ตร.ม.) | B15: 8 | D15: ค่าทั่วไป 6–10
A16: รายการที่ต้องซื้อ | B16: จำนวน | C16: หน่วย | D16: หมายเหตุ
A17: แผ่นหลังคา PU ลอน 760 (เหมา 1 job) | B17: 1 | C17: เหมา | D17: ="อ้างอิง ~"&TEXT(F9,"#,##0")&" แผ่น / "&TEXT(D9,"#,##0.0")&" ตร.ม. ตามลาด"
A18: สกรูยึดหลังคา | B18: =ROUNDUP(D9*$B$15,0) | C18: ตัว
A19: ครอบสัน ครอบข้าง ฟลาชชิ่ง ซีล (ต้องตรวจนับหน้างาน) | C19: เหมา | D19: ไม่มีปริมาณในโมเดล
A20: โครงหลังคาเหล็ก (แป จันทัน ตะเฆ่สัน) ยังไม่มีในไฟล์นี้ | C20: เหมา | D20: ต้องให้วิศวกร/ผู้รับเหมากำหนด

Sheet ประตู-หน้าต่าง
A1: ประตูและหน้าต่าง (ขนาดกรอบนอก)
A3: ประตู | B3: กว้าง (ม.) | C3: สูง (ม.) | D3: พื้นที่ (ตร.ม.)
A4: ประตู_นอน1-นั่งเล่น | B4: 0.8 | C4: 2 | D4: =B4*C4
A5: ประตู_นอน1-น้ำ1 | B5: 0.7 | C5: 2 | D5: =B5*C5
A6: ประตู_นั่งเล่น-นอน2 | B6: 0.8 | C6: 2 | D6: =B6*C6
A7: ประตู_นั่งเล่น-น้ำ2 | B7: 0.7 | C7: 2 | D7: =B7*C7
A8: ประตู_นั่งเล่น_เหนือ | B8: 0.8 | C8: 2 | D8: =B8*C8
A9: ประตู_น้ำ2-นอน2 | B9: 0.9 | C9: 2.1 | D9: =B9*C9
A10: ประตู_ลานหน้าบ้าน-นั่งเล่น_1 | B10: 1 | C10: 2 | D10: =B10*C10
A11: ประตู_ลานหน้าบ้าน-นั่งเล่น_2 | B11: 1 | C11: 2 | D11: =B11*C11
A12: ประตู_เก็บของ-นั่งเล่น | B12: 0.7 | C12: 2 | D12: =B12*C12
A13: รวมประตู (บาน) | B13: =COUNTA(A4:A12) | D13: =SUM(D4:D12)
A15: หน้าต่าง | B15: กว้าง (ม.) | C15: สูง (ม.) | D15: พื้นที่ (ตร.ม.) | F15: MP aluminium buritam | G15: PP windows bkk | H15: MP ทางเลือก บานกระทุ้ง | I15: PP ทางเลือก
A16: หน้าต่าง_นอน1_ตะวันตก | B16: 2 | C16: 1.1 | D16: =B16*C16 | F16: 4800 | G16: 5290 | H16: 8500 | I16: 10990
A17: หน้าต่าง_นอน1_เหนือ_1 | B17: 0.5 | C17: 1.5 | D17: =B17*C17 | F17: 3000 | G17: 2940
A18: หน้าต่าง_นอน1_เหนือ_2 | B18: 0.5 | C18: 1.5 | D18: =B18*C18 | F18: 3000 | G18: 2940
A19: หน้าต่าง_นอน1_ใต้ | B19: 0.5 | C19: 1.5 | D19: =B19*C19 | F19: 3000 | G19: 2940
A20: หน้าต่าง_นอน2_ตะวันออก | B20: 2 | C20: 1.1 | D20: =B20*C20 | F20: 4800 | G20: 5290 | H20: 8500 | I20: 10990
A21: หน้าต่าง_นอน2_เหนือ_1 | B21: 0.5 | C21: 1.5 | D21: =B21*C21 | F21: 3000 | G21: 2940
A22: หน้าต่าง_นอน2_เหนือ_2 | B22: 0.5 | C22: 1.5 | D22: =B22*C22 | F22: 3000 | G22: 2940
A23: หน้าต่าง_นั่งเล่น_ตะวันออก_1 | B23: 2 | C23: 1.8 | D23: =B23*C23 | F23: 10000 | G23: 9690 | I23: 16290
A24: หน้าต่าง_นั่งเล่น_ตะวันออก_2 | B24: 1.2 | C24: 1.1 | D24: =B24*C24 | F24: 2800 | G24: 2640 | H24: 5000 | I24: 5590
A25: หน้าต่าง_นั่งเล่น_ใต้_1 | B25: 0.5 | C25: 1.5 | D25: =B25*C25 | F25: 3000 | G25: 2940
A26: หน้าต่าง_นั่งเล่น_ใต้_2 | B26: 0.5 | C26: 1.5 | D26: =B26*C26 | F26: 3000 | G26: 2940
A27: หน้าต่าง_น้ำ1_เหนือ_1 | B27: 0.8 | C27: 0.5 | D27: =B27*C27 | F27: 1450 | G27: 1140
A28: หน้าต่าง_น้ำ1_เหนือ_2 | B28: 0.8 | C28: 0.5 | D28: =B28*C28 | F28: 1450 | G28: 1140
A29: หน้าต่าง_น้ำ2_เหนือ_1 | B29: 0.8 | C29: 0.5 | D29: =B29*C29 | F29: 1450 | G29: 1140
A30: หน้าต่าง_น้ำ2_เหนือ_2 | B30: 0.8 | C30: 0.5 | D30: =B30*C30 | F30: 1450 | G30: 1140
A31: หน้าต่าง_ลานหน้าบ้าน-นั่งเล่น | B31: 2 | C31: 2 | D31: =B31*C31 | F31: 6800 | G31: 8490
A32: หน้าต่าง_เก็บของ_ตะวันออก | B32: 0.8 | C32: 0.5 | D32: =B32*C32 | F32: 1450 | G32: 1140
A33: หน้าต่าง_เก็บของ_ใต้ | B33: 0.8 | C33: 0.5 | D33: =B33*C33 | F33: 1450 | G33: 1140
A34: รวมหน้าต่าง (บาน) | B34: =COUNTA(A16:A33) | D34: =SUM(D16:D33) | F34: =SUM(F16:F33) | G34: =SUM(G16:G33)
G35: =G34-2500
A36: ประตูหน้าบ้านเป็นประตูคู่ 2 บาน บานละ 1.0 ม. รวมนับ 2 บาน
A39: สิ่งที่ต้องซื้อ (จากชีตนี้)
A40: รายการที่ต้องซื้อ | B40: จำนวน | C40: หน่วย | D40: หมายเหตุ
A41: ประตู 0.70x2.00 ม. | B41: =COUNTIFS(B4:B12,0.7,C4:C12,2) | C41: บาน | D41: ห้องน้ำ 1 / ห้องน้ำ 2 (ฝั่งนั่งเล่น) / เก็บของ
A42: ประตู 0.80x2.00 ม. | B42: =COUNTIFS(B4:B12,0.8,C4:C12,2) | C42: บาน | D42: D4 D5 บานทึบ + D6 ประตูหลังบ้านไม้ระแนง
A43: ประตู 0.90x2.10 ม. (ห้องน้ำ 2 ↔ ห้องนอน 2) | B43: =COUNTIFS(B4:B12,0.9,C4:C12,2.1) | C43: บาน
A44: ประตู 1.00x2.00 ม. (ประตูหลักคู่ไม้ระแนง นับ 2 บาน) | B44: =COUNTIFS(B4:B12,1,C4:C12,2) | C44: บาน
...

Sheet Sheet1
A1: หน้าต่าง | B1: กว้าง (ม.) | C1: สูง (ม.) | D1: พื้นที่ (ตร.ม.) | F1: รหัส | G1: กว้าง (ม.) | H1: สูง (ม.) | I1: ขนาด | J1: จำนวน (บาน) | K1: พื้นที่/บาน (ตร.ม.) | L1: พื้นที่รวม (ตร.ม.) | M1: ราคาต่อบาน (บาท) | N1: รวม (บาท)
A2: หน้าต่าง_นอน1_ตะวันตก | B2: 2 | C2: 1.1 | D2: =B2*C2 | F2: หน้าต่าง ลายตารางสีดำ 4 ช่อง กระจกชาดำ | G2: 2 | H2: 1.1 | I2: =TEXT(G2,"0.00")&" x "&TEXT(H2,"0.00")&" ม." | J2: =COUNTIFS($B$2:$B$19,G2,$C$2:$C$19,H2) | K2: =G2*H2 | L2: =J2*K2 | M2: =AVERAGEIFS('ประตู-หน้าต่าง'!$G$16:$G$33,'ประตู-หน้าต่าง'!$B$16:$B$33,G2,'ประตู-หน้าต่าง'!$C$16:$C$33,H2) | N2: =IF(M2="","",J2*M2)
A3: หน้าต่าง_นอน1_เหนือ_1 | B3: 0.5 | C3: 1.5 | D3: =B3*C3 | F3: หน้าต่าง บานกระทุง ลายตารางสีดำ กระจกชาดำ | G3: 0.5 | H3: 1.5 | I3: =TEXT(G3,"0.00")&" x "&TEXT(H3,"0.00")&" ม." | J3: =COUNTIFS($B$2:$B$19,G3,$C$2:$C$19,H3) | K3: =G3*H3 | L3: =J3*K3 | M3: =AVERAGEIFS('ประตู-หน้าต่าง'!$G$16:$G$33,'ประตู-หน้าต่าง'!$B$16:$B$33,G3,'ประตู-หน้าต่าง'!$C$16:$C$33,H3) | N3: =IF(M3="","",J3*M3)
A4: หน้าต่าง_นอน1_เหนือ_2 | B4: 0.5 | C4: 1.5 | D4: =B4*C4 | F4: หน้าต่าง บานกระทุ้ง ลายตารางสีดำ 4 ช่อง กระจกชาดำ // สั่งทำ | G4: 2 | H4: 1.8 | I4: =TEXT(G4,"0.00")&" x "&TEXT(H4,"0.00")&" ม." | J4: =COUNTIFS($B$2:$B$19,G4,$C$2:$C$19,H4) | K4: =G4*H4 | L4: =J4*K4 | M4: =AVERAGEIFS('ประตู-หน้าต่าง'!$G$16:$G$33,'ประตู-หน้าต่าง'!$B$16:$B$33,G4,'ประตู-หน้าต่าง'!$C$16:$C$33,H4) | N4: =IF(M4="","",J4*M4)
A5: หน้าต่าง_นอน1_ใต้ | B5: 0.5 | C5: 1.5 | D5: =B5*C5 | F5: หน้าต่าง ลายตารางสีดำ 2 ช่อง กระจกชาดำ | G5: 1.2 | H5: 1.1 | I5: =TEXT(G5,"0.00")&" x "&TEXT(H5,"0.00")&" ม." | J5: =COUNTIFS($B$2:$B$19,G5,$C$2:$C$19,H5) | K5: =G5*H5 | L5: =J5*K5 | M5: =AVERAGEIFS('ประตู-หน้าต่าง'!$G$16:$G$33,'ประตู-หน้าต่าง'!$B$16:$B$33,G5,'ประตู-หน้าต่าง'!$C$16:$C$33,H5) | N5: =IF(M5="","",J5*M5)
A6: หน้าต่าง_นอน2_ตะวันออก | B6: 2 | C6: 1.1 | D6: =B6*C6 | F6: หน้าต่าง บานเลื่อนเล็ก สีดำ กระจกฝ้า | G6: 0.8 | H6: 0.5 | I6: =TEXT(G6,"0.00")&" x "&TEXT(H6,"0.00")&" ม." | J6: 3 | K6: =G6*H6 | L6: =J6*K6 | M6: =AVERAGEIFS('ประตู-หน้าต่าง'!$G$16:$G$33,'ประตู-หน้าต่าง'!$B$16:$B$33,G6,'ประตู-หน้าต่าง'!$C$16:$C$33,H6) | N6: =IF(M6="","",J6*M6)
A7: หน้าต่าง_นอน2_เหนือ_1 | B7: 0.5 | C7: 1.5 | D7: =B7*C7 | F7: ประตูบานเลื่อน ลายตาราง 4 ช่อง สีดำ กระจก ชาดำ | G7: 2 | H7: 2 | I7: =TEXT(G7,"0.00")&" x "&TEXT(H7,"0.00")&" ม." | J7: =COUNTIFS($B$2:$B$19,G7,$C$2:$C$19,H7) | K7: =G7*H7 | L7: =J7*K7 | M7: =AVERAGEIFS('ประตู-หน้าต่าง'!$G$16:$G$33,'ประตู-หน้าต่าง'!$B$16:$B$33,G7,'ประตู-หน้าต่าง'!$C$16:$C$33,H7) | N7: =IF(M7="","",J7*M7)
A8: หน้าต่าง_นอน2_เหนือ_2 | B8: 0.5 | C8: 1.5 | D8: =B8*C8 | F8: รวม | J8: =SUM(J2:J7) | L8: =SUM(L2:L7) | N8: =SUM(N2:N7)
A9: หน้าต่าง_นั่งเล่น_ตะวันออก_1 | B9: 2 | C9: 1.8 | D9: =B9*C9 | F9: ตรวจสอบ | J9: =COUNTA(A2:A19) | L9: =SUM(D2:D19)
A10: หน้าต่าง_นั่งเล่น_ตะวันออก_2 | B10: 1.2 | C10: 1.1 | D10: =B10*C10
A11: หน้าต่าง_นั่งเล่น_ใต้_1 | B11: 0.5 | C11: 1.5 | D11: =B11*C11
A12: หน้าต่าง_นั่งเล่น_ใต้_2 | B12: 0.5 | C12: 1.5 | D12: =B12*C12
A13: หน้าต่าง_น้ำ1_เหนือ_1 | B13: 0.8 | C13: 0.5 | D13: =B13*C13
A14: หน้าต่าง_น้ำ1_เหนือ_2 | B14: 0.8 | C14: 0.5 | D14: =B14*C14
A15: หน้าต่าง_น้ำ2_เหนือ_1 | B15: 0.8 | C15: 0.5 | D15: =B15*C15
A16: หน้าต่าง_น้ำ2_เหนือ_2 | B16: 0.8 | C16: 0.5 | D16: =B16*C16
A17: หน้าต่าง_ลานหน้าบ้าน-นั่งเล่น | B17: 2 | C17: 2 | D17: =B17*C17
A18: หน้าต่าง_เก็บของ_ตะวันออก | B18: 0.8 | C18: 0.5 | D18: =B18*C18
A19: หน้าต่าง_เก็บของ_ใต้ | B19: 0.8 | C19: 0.5 | D19: =B19*C19
A22: สิ่งที่ต้องซื้อ (จากชีตนี้)
A23: รายการที่ต้องซื้อ | B23: จำนวน | C23: หน่วย | D23: หมายเหตุ
A24: =F2&" "&I2 | B24: =J2 | C24: บาน
A25: =F3&" "&I3 | B25: =J3 | C25: บาน
A26: =F4&" "&I4 | B26: =J4 | C26: บาน
A27: =F5&" "&I5 | B27: =J5 | C27: บาน
A28: =F6&" "&I6 | B28: =J6 | C28: บาน | D28: จำนวนในช่อง J6 เป็นค่าที่กรอกไว้เอง
A29: =F7&" "&I7 | B29: =J7 | C29: บาน

Sheet เสาและคอนกรีต
A1: เสาและคอนกรีต
A3: รายการ | B3: กว้าง (ม.) | C3: ยาว/สูง (ม.) | D3: จำนวน/พื้นที่ | E3: ปริมาตร (ลบ.ม.)
A4: เสา (ขนาดจากโมเดล) ต้น | B4: 0.144 | C4: 3.595 | D4: 19 | E4: =B4*B4*C4*D4
A5: พื้นคอนกรีต (พื้นที่ผิวบน × ความหนา) | B5: =ข้อสมมติ!$B$14 | D5: =พื้นและกระเบื้อง!D4 | E5: =D5*B5
A6: พื้นที่ผิวนอกคานรอบบ้าน (ขอบพื้น) ตร.ม. | D6: 25.91
A7: รวมคอนกรีตเสาและพื้น | E7: =E4+E5
A9: ปริมาตรพื้นคิดจากพื้นที่ผิวบนทั้งหมด × 0.5 ม. ตามโมเดล ซึ่งเป็นความสูงของขอบพื้น ไม่ใช่ความหนาจริงของโครงสร้าง ใช้เป็นค่าประมาณเท่านั้น
A12: สิ่งที่ต้องซื้อ (จากชีตนี้)
A13: รายการที่ต้องซื้อ | B13: จำนวน | C13: หน่วย | D13: หมายเหตุ
A14: คอนกรีตผสมเสร็จ เสา+พื้น (รวมเผื่อ) | B14: =E7*(1+'ปูนก่อ-ฉาบ-ทับหลัง'!$B$21) | C14: ลบ.ม. | D14: ปริมาตรพื้นคิดจากความสูงขอบพื้น 0.5 ม. อาจเกินจริงมาก
A15: เหล็กเสริมเสา พื้น คาน ฐานราก เสาเข็ม (ไม่มีในโมเดล) | C15: เหมา | D15: วิศวกรโครงสร้างกำหนด
A16: ไม้แบบเสา/พื้น/คาน (ไม่มีในโมเดล) | C16: เหมา

Sheet สีทา
A1: พื้นที่ทาสี แยกภายนอก/ภายใน (TOA 21001 และสีภายนอก)
A3: รายการ | B3: ภายนอก (ตร.ม.) | C3: ภายใน (ตร.ม.) | D3: รวม (ตร.ม.) | E3: หมายเหตุ
A4: ผนังก่อด้านนอกอาคาร (ผนังนอก 9 แนว หักช่องเปิดแล้ว) ผิวนอกและผิวใน | B4: =SUM(ผนังก่ออิฐ!$G$4:$G$12) | C4: =SUM(ผนังก่ออิฐ!$G$4:$G$12) | D4: =B4+C4 | E4: ผนังนอกทาทั้งสองด้าน: ด้านนอก = ภายนอก ด้านใน = ภายใน
A5: ผนังกั้นภายใน 2 ด้าน | B5: 0 | C5: =2*(SUM(ผนังก่ออิฐ!$G$13:$G$21)+ผนังก่ออิฐ!$G$24) | D5: =B5+C5 | E5: ทั้งสองด้านเป็นภายใน
A6: ผนังกั้นฝั่งลานหน้าบ้าน (ลานถือเป็นภายนอก) 2 ด้าน | B6: =ผนังก่ออิฐ!$G$22+ผนังก่ออิฐ!$G$23 | C6: =ผนังก่ออิฐ!$G$22+ผนังก่ออิฐ!$G$23 | D6: =B6+C6 | E6: ด้านลาน = ภายนอก ด้านห้อง = ภายใน
A7: หัก พื้นที่กระเบื้องผนังห้องน้ำ (ไม่ทาสี) | B7: 0 | C7: =-พื้นและกระเบื้อง!$D$27 | D7: =B7+C7
A8: คานรอบบ้าน (ขอบพื้นลงถึงดิน) | B8: =เสาและคอนกรีต!D6 | C8: 0 | D8: =B8+C8
A9: เสา (4 ด้าน × สูง × จำนวน) | B9: =4*เสาและคอนกรีต!B4*เสาและคอนกรีต!C4*เสาและคอนกรีต!D4 | C9: 0 | D9: =B9+C9 | E9: ถือเป็นภายนอกทั้งหมด (เสาติดผนังบางส่วนอยู่ในแนวผนัง)
A10: รวมพื้นที่ทาสี | B10: =SUM(B4:B9) | C10: =SUM(C4:C9) | D10: =SUM(D4:D9)
A11: ตรวจสอบกับวิธีเดิม (2×ผนังสุทธิ − กระเบื้อง + คาน + เสา) ผลต่างควรเป็น 0 | D11: =D10-(2*ผนังก่ออิฐ!$G$25-พื้นและกระเบื้อง!$D$27+เสาและคอนกรีต!D6+4*เสาและคอนกรีต!B4*เสาและคอนกรีต!C4*เสาและคอนกรีต!D4)
A12: ไม่รวมผนังจั่วใต้หลังคา ผนังที่ปูกระเบื้องครัว ผนังฝ้า และการหักพื้นที่ที่เฟอร์นิเจอร์บัง
A14: สิ่งที่ต้องซื้อ (จากชีตนี้)
A15: ข้อสมมติ | B15: ค่า | E15: หมายเหตุ
A16: จำนวนเที่ยวทาสีภายใน (เที่ยว) | B16: 2 | E16: ค่าสมมติ
A17: จำนวนเที่ยวทาสีภายนอก (เที่ยว) | B17: 2 | E17: ค่าสมมติ
A18: พื้นที่ทาได้ต่อลิตร สีภายใน (ตร.ม./ลิตร) | B18: 9.2 | E18: เดิม 35 ตร.ม./แกลลอน 3.785 ลิตร ≈ 9.2
A19: พื้นที่ทาได้ต่อลิตร สีภายนอก (ตร.ม./ลิตร) | B19: 8 | E19: ผิวนอกขรุขระกว่า ใช้ต่ำกว่า
A20: จำนวนเที่ยวรองพื้นปูนใหม่ (เที่ยว) | B20: 1
A21: พื้นที่รองพื้นได้ต่อลิตร (ตร.ม./ลิตร) | B21: 8 | E21: เดิม 30 ตร.ม./แกลลอน ≈ 8
A22: ขนาดแพ็กที่ซื้อ ถังใหญ่ (ลิตร) | B22: 9 | E22: ซื้อแพ็กใหญ่ 9 ลิตร (ถ้าเปลี่ยนไปซื้อ 3 ลิตร ให้แก้เป็น 3)
A23: ปริมาณสีที่ต้องใช้ | B23: ลิตร | E23: หมายเหตุ
A24: สีทาภายใน | B24: =ROUNDUP(C10*$B$16/$B$18,1)
A25: สีทาภายนอก | B25: =ROUNDUP(B10*$B$17/$B$19,1)
A26: สีรองพื้นภายใน | B26: =ROUNDUP(C10*$B$20/$B$21,1)
A27: สีรองพื้นภายนอก | B27: =ROUNDUP(B10*$B$20/$B$21,1)
A28: รายการที่ต้องซื้อ | B28: จำนวน | C28: หน่วย | D28: หมายเหตุ
A29: ="สีทาภายใน TOA 21001 ถังใหญ่ "&$B$22&" ลิตร" | B29: =ROUNDUP($B$24/$B$22,0) | C29: ถัง | D29: ซื้อแพ็กใหญ่ ปัดขึ้นเป็นถัง
A30: ="สีรองพื้นปูนใหม่ ภายใน ถังใหญ่ "&$B$22&" ลิตร" | B30: =ROUNDUP($B$26/$B$22,0) | C30: ถัง | D30: ซื้อแพ็กใหญ่ ปัดขึ้นเป็นถัง
A31: ="สีทาภายนอก (สีทนสภาพอากาศ ยี่ห้อ/เบอร์ตามที่เลือก) ถังใหญ่ "&$B$22&" ลิตร" | B31: =ROUNDUP($B$25/$B$22,0) | C31: ถัง | D31: ซื้อแพ็กใหญ่ ปัดขึ้นเป็นถัง
A32: ="สีรองพื้นปูนใหม่ ภายนอก ถังใหญ่ "&$B$22&" ลิตร" | B32: =ROUNDUP($B$27/$B$22,0) | C32: ถัง | D32: ซื้อแพ็กใหญ่ ปัดขึ้นเป็นถัง
A33: อุปกรณ์ทาสี (ลูกกลิ้ง แปรง เทปกาว ผ้าคลุม) | C33: เหมา
A35: จำนวนถัง = ลิตรที่ต้องใช้ ÷ ขนาดแพ็ก ปัดขึ้น (ปรับขนาดแพ็กได้ในช่องข้อสมมติด้านบน)

Sheet ไฟฟ้า
A1: อุปกรณ์ไฟฟ้า (นับจากโมเดล v413)
A3: รายการ | B3: จุดติดตั้ง/บล็อก | C3: เต้ารับเสียบได้ | D3: กลไกสวิตช์
A4: เต้ารับคู่มีสายดิน ภายในบ้าน | B4: 14 | C4: 28 | D4: 0
A5: เต้ารับคู่มีสายดิน ภายนอกพร้อมฝาปิด | B5: 3 | C5: 6 | D5: 0
A6: เต้ารับ 4 ช่อง ผนังข้าง C8 | B6: 1 | C6: 4 | D6: 0
A7: เต้ารับเดี่ยวในกล่องปิด CCTV P2/P3 | B7: 2 | C7: 2 | D7: 0
A8: ชุดสวิตช์ 3 ปุ่ม | B8: 6 | C8: 0 | D8: 18
A9: ชุดสวิตช์ 2 ปุ่ม | B9: 5 | C9: 0 | D9: 10
A10: กล่องต่อสายฝาทึบ (แอร์3 น้ำอุ่น2 ปั๊ม1 EV1) | B10: 7 | C10: 0 | D10: 0
A11: ช่องเสาอากาศทีวี | B11: 1 | C11: 0 | D11: 0
A12: รวม | B12: =SUM(B4:B11) | C12: =SUM(C4:C11) | D12: =SUM(D4:D11)
A14: โคมไฟ (จุด) ไม่รวมโคมห้อยโต๊ะ | B14: 34
A15: ตู้คอนซูมเมอร์ยูนิต 18 ช่อง (ใช้ 16 สำรอง 2) | B15: 1
A16: โคมห้อยโต๊ะทานข้าว 3 หัว (ชุด) รวมเป็นโคมทั้งหมด 37 จุดแสง | B16: 1
A17: ยังไม่รวมสายไฟ ท่อร้อยสาย ราง เบรกเกอร์ ขนาดและจำนวนต้องให้ผู้ออกแบบไฟฟ้ากำหนด
A18: สวิตช์ไฟห้องน้ำ 2 เป็นแบบ 2 ทาง (2 ตัว) ต้องเลือกสวิตช์ 2 ทางและเดินสายเดินทาง รวมในยอดชุดสวิตช์ 2 ปุ่ม 5 ชุดแล้ว
A19: สวิตช์ 3 ปุ่มข้างเสา C15 (ในบ้าน) จับคู่ 2 ทางกับสวิตช์ 3 ปุ่มหน้าบ้านเหนือเต้ารับลานหน้า (กันน้ำ IP55) ใช้สวิตช์ 2 ทางทั้ง 3 ปุ่ม + สายเดินทาง 6 เส้น รวมในยอดชุดสวิตช์ 3 ปุ่ม 6 ชุดแล้ว
A20: เสาอากาศทีวี (ดูพิมพ์เขียว A-06) — ยังไม่รวมสายดินและตัวป้องกันฟ้าผ่า ต้องให้ช่างไฟกำหนด
A21: เสาอากาศทีวีดิจิทัล UHF แบบยากี 13 ชิ้นส่วน (ติดชายคาตะวันออก แนว P4) | B21: 1 | C21: ชุด
A22: ท่อเหล็กดำ Ø42 มม. โค้งยึดขอบชายคา (วัดจากโมเดล) | B22: 1.83 | C22: ม.
A23: สายโคแอกเชียล RG6 (วัดจากโมเดล ยังไม่รวมเผื่อ/หัว F) | B23: 11.43 | C23: ม.
A24: แคลมป์ยึดขอบชายคา + กล่องกลอนสาย + ยางร้อยสายผ่านฝ้า | B24: 1 | C24: ชุด
A27: สิ่งที่ต้องซื้อ (จากชีตนี้)
A28: รายการที่ต้องซื้อ | B28: จำนวน | C28: หน่วย | D28: หมายเหตุ
A29: เต้ารับคู่มีสายดิน (ใน+นอกบ้าน ฝาปิดกันน้ำภายนอก 3) | B29: =B4+B5 | C29: ชุด
A30: เต้ารับ 4 ช่อง | B30: =B6 | C30: ชุด
A31: เต้ารับเดี่ยวในกล่องปิด CCTV | B31: =B7 | C31: ชุด
A32: ชุดสวิตช์ 3 ปุ่ม (รวมสวิตช์ 2 ทางคู่ C15 ในบ้าน + หน้าบ้าน 2 ตัว) | B32: =B8 | C32: ชุด | D32: ตัวหน้าบ้านต้องใช้ชนิดกันน้ำ/กล่องครอบ IP55 (ดูแถวล่าง)
A33: ชุดสวิตช์ 2 ปุ่ม (รวมสวิตช์ 2 ทางห้องน้ำ 2 จำนวน 2 ตัว) | B33: =B9 | C33: ชุด
A34: กล่องต่อสายฝาทึบ (แอร์ น้ำอุ่น ปั๊ม EV) | B34: =B10 | C34: ชุด
A35: ช่องเสาอากาศทีวี | B35: =B11 | C35: ชุด
A36: โคมซาลาเปา (ติดเพดาน) | B36: 9 | C36: ชุด | D36: นับจากโมเดล
A37: ดาวน์ไลท์/ไฟหลุม (รวมไฟหลุมลานหน้า 6 ดวง) | B37: 13 | C37: ชุด | D37: ไฟหลุมลานหน้า 6 ดวง ติดฝ้าลอนลายไม้ แบ่ง 3/3 ต้องเลือกรุ่นที่ติดตั้งในฝ้าลอนได้/กันน้ำภายนอก
A38: โคมห้อย (ห้องนอน) | B38: 2 | C38: ชุด
A39: ไฟผนัง (รวมไฟกล่องดำส่องขึ้น-ลงข้างประตูหลัก 2 ดวง) | B39: 8 | C39: ชุด | D39: ไฟข้างประตู = กล่องดำสี่เหลี่ยม 2 หน้าแสง ต้องเลือกรุ่นกันน้ำภายนอก (IP54 ขึ้นไป)
A40: ไฟยาว (บาร์) | B40: 2 | C40: ชุด | D40: รวม 5 ชนิด = 34 จุด ตรงกับ B14
A41: โคมห้อยโต๊ะทานข้าว 3 หัว | B41: =B16 | C41: ชุด
A42: ตู้คอนซูมเมอร์ยูนิต 18 ช่อง | B42: =B15 | C42: ตู้ | D42: เบรกเกอร์ย่อยแยกซื้อตามวงจร
A43: เสาอากาศทีวีดิจิทัล UHF แบบยากี | B43: =B21 | C43: ชุด
A44: ท่อเหล็กดำ Ø42 มม. ยึดเสาอากาศ | B44: =B22 | C44: ม.
...

Sheet ประปา-สุขาภิบาล
A1: ท่อน้ำดี น้ำทิ้ง โสโครก และอุปกรณ์ (วัดจากโมเดล v413)
G2: เผื่อ | H2: 0.1
A3: ระบบ / ขนาด | B3: ความยาวจากโมเดล (ม.) | C3: เผื่อตัด/ข้อต่อ | D3: ความยาวรวม (ม.) | E3: ท่อน (4 ม.)
A4: ท่อน้ำดี Ø25 มม. (เส้นผ่านศูนย์กลางตามโมเดล) | B4: 12.37 | C4: =$H$2 | D4: =B4*(1+C4) | E4: =ROUNDUP(D4/4,0)
A5: ท่อน้ำดี Ø28 มม. (เส้นผ่านศูนย์กลางตามโมเดล) | B5: 0.67 | C5: =$H$2 | D5: =B5*(1+C5) | E5: =ROUNDUP(D5/4,0)
A6: ท่อน้ำดี Ø32 มม. (เส้นผ่านศูนย์กลางตามโมเดล) | B6: 35.01 | C6: =$H$2 | D6: =B6*(1+C6) | E6: =ROUNDUP(D6/4,0)
A7: ท่อน้ำทิ้ง Ø50 มม. (เส้นผ่านศูนย์กลางตามโมเดล) | B7: 7.39 | C7: =$H$2 | D7: =B7*(1+C7) | E7: =ROUNDUP(D7/4,0)
A8: ท่อน้ำทิ้ง Ø75 มม. (เส้นผ่านศูนย์กลางตามโมเดล) | B8: 15.14 | C8: =$H$2 | D8: =B8*(1+C8) | E8: =ROUNDUP(D8/4,0)
A9: ท่อโสโครก/อากาศ Ø50 มม. (เส้นผ่านศูนย์กลางตามโมเดล) | B9: 21.59 | C9: =$H$2 | D9: =B9*(1+C9) | E9: =ROUNDUP(D9/4,0)
A10: ท่อโสโครก/อากาศ Ø110 มม. (เส้นผ่านศูนย์กลางตามโมเดล) | B10: 8.03 | C10: =$H$2 | D10: =B10*(1+C10) | E10: =ROUNDUP(D10/4,0)
A12: อุปกรณ์
A13: ถังน้ำดี 1000 ลิตร พร้อมฐานคอนกรีต | B13: 1 | D13: ชุด
A14: เครื่องกรองน้ำ (ถัง) | B14: 2 | D14: ชุด
A15: ปั๊มน้ำ + ถังแรงดัน | B15: 1 | D15: ชุด
A16: ถังแซท (บำบัดฝังดิน) | B16: 1 | D16: ถัง
A17: บ่อซึม วงคอนกรีต Ø1.0 สูง 0.5 ม. + ฝา | B17: 3 | D17: วง
A18: ก๊อกน้ำภายนอก (เครื่องซักผ้า P2 C3 C14) | B18: 4 | D18: จุด
A19: ตะแกรงน้ำทิ้งพื้นห้องน้ำ | B19: 4 | D19: ชุด
A20: ฝาจุดเปิดล้างก่อนถังแซท | B20: 1 | D20: ชุด
A21: วาล์วน้ำ (ห้องน้ำ 8 ซิงค์ครัว 1 แยก C2 1) | B21: 10 | D21: ตัว
A23: ความยาวเป็นแนวกลางเส้นท่อในโมเดลเบื้องต้น ขนาดท่อ ความลาด ข้อต่อ และชั้นคุณภาพต้องตรวจสอบก่อนจัดซื้อ ไม่รวมข้อต่อ วาล์ว และงานขุด
A26: สิ่งที่ต้องซื้อ (จากชีตนี้)
A27: รายการที่ต้องซื้อ | B27: จำนวน | C27: หน่วย | D27: หมายเหตุ
A28: =A4 | B28: =E4 | C28: ท่อน (4 ม.)
A29: =A5 | B29: =E5 | C29: ท่อน (4 ม.)
A30: =A6 | B30: =E6 | C30: ท่อน (4 ม.)
A31: =A7 | B31: =E7 | C31: ท่อน (4 ม.)
A32: =A8 | B32: =E8 | C32: ท่อน (4 ม.)
A33: =A9 | B33: =E9 | C33: ท่อน (4 ม.)
A34: =A10 | B34: =E10 | C34: ท่อน (4 ม.)
A35: =A13 | B35: =B13 | C35: =D13
A36: =A14 | B36: =B14 | C36: =D14
A37: =A15 | B37: =B15 | C37: =D15
A38: =A16 | B38: =B16 | C38: =D16
A39: =A17 | B39: =B17 | C39: =D17
A40: =A18 | B40: =B18 | C40: =D18
A41: =A19 | B41: =B19 | C41: =D19
A42: =A20 | B42: =B20 | C42: =D20
A43: =A21 | B43: =B21 | C43: =D21
A44: ข้อต่อ วาล์ว กาวท่อ ข้อต่อเกลียว (ยังไม่รวมในปริมาณ) | C44: เหมา

Sheet สุขภัณฑ์-ครัว
A1: สุขภัณฑ์ห้องน้ำและงานครัว (ซิงค์แบบก่อ)
A2: จำนวนนับจากโมเดล v413 (ช่องสีน้ำเงิน) รายการที่ไม่มีในโมเดลเป็นค่าสมมติ ยี่ห้อ/รุ่น/สีและขนาดจริงต้องเลือกก่อนสั่งซื้อ
A4: สุขภัณฑ์ห้องน้ำ | B4: ห้องน้ำ 1 | C4: ห้องน้ำ 2 | D4: รวม | E4: ขนาดในโมเดล / หมายเหตุ
A5: โถสุขภัณฑ์ (ชักโครก) ชนิดวางพื้น พร้อมถังพักน้ำและฝารองนั่ง | B5: 1 | C5: 1 | D5: =B5+C5 | E5: 0.75x0.41x0.84 ม. ยังไม่ระบุรุ่น
A6: อ่างล้างหน้าแบบวางบนเคาน์เตอร์ปูน | B6: 1 | C6: 1 | D6: =B6+C6 | E6: 0.40x0.40 ม. (เคาน์เตอร์ปูนอยู่ในงานก่อ)
A7: ก๊อกอ่างล้างหน้า (ก๊อกคอสูง) | B7: 1 | C7: 1 | D7: =B7+C7 | E7: สูง 0.31 ม.
A8: สะดือและท่อน้ำทิ้งอ่าง พร้อมท่อดักกลิ่น (P-trap) | B8: 1 | C8: 1 | D8: =B8+C8 | E8: ค่าสมมติ 1 ชุดต่ออ่าง
A9: สายน้ำดีอ่อน (สายถัก) สำหรับอ่างและโถ | B9: 2 | C9: 2 | D9: =B9+C9 | E9: ค่าสมมติ 2 เส้นต่อห้อง (อ่าง 1 โถ 1)
A10: ชุดสายฉีดชำระ พร้อมหัว สายและขอแขวน | B10: 1 | C10: 1 | D10: =B10+C10 | E10: ท่อน้ำดีและวาล์วฉีดชำระอยู่ในชีตประปาแล้ว
A11: เครื่องฝักบัว/ชุดฝักบัวอาบน้ำ (ก้าน หัวฝักบัว และวาล์วผสมหรือก๊อกเปิด-ปิด) | B11: 1 | C11: 1 | D11: =B11+C11 | E11: 0.42x0.20x0.92 ม. ในโมเดล
A12: ฉากกั้นอาบน้ำกระจกเทมเปอร์ใส พร้อมอุปกรณ์ยึด | B12: 1 | C12: 1 | D12: =B12+C12 | E12: 0.90x1.89 ม. แผ่นเดียวติดตาย
A13: กระจกเงาห้องน้ำ | B13: 1 | C13: 1 | D13: =B13+C13 | E13: 0.38x0.75 ม.
A14: อุปกรณ์ห้องน้ำ: ที่ใส่กระดาษชำระ ที่แขวนผ้า ขอแขวน (ไม่มีในโมเดล) | B14: 1 | C14: 1 | D14: =B14+C14 | E14: ค่าสมมติ 1 ชุดต่อห้อง
A16: ครัว (ซิงค์แบบก่อ ติดผนังตะวันออก) | B16: จำนวน | C16: หน่วย | E16: ขนาดในโมเดล / หมายเหตุ
A17: ซิงค์สแตนเลส 2 หลุม มีที่พักจาน | B17: 1 | C17: ชุด | E17: 1.20x0.50 ม. (ฝังท็อปกระเบื้อง ต้องเจาะช่องตามแบบซิงค์)
A18: ก๊อกซิงค์ครัว (คอสูง) | B18: 1 | C18: ชุด
A19: สะดือซิงค์และท่อน้ำทิ้ง พร้อมท่อดักกลิ่น (P-trap) | B19: 1 | C19: ชุด | E19: ท่อน้ำทิ้งซิงค์อยู่ในชีตประปาแล้ว
A20: สายน้ำดีอ่อน (สายถัก) ใต้ซิงค์ | B20: 2 | C20: เส้น | E20: ค่าสมมติ น้ำร้อน-น้ำเย็นหรือเย็นอย่างเดียว
A21: บานตู้ใต้ซิงค์ บานเปิด 0.50x0.64 ม. สีดำ | B21: 4 | C21: บาน | E21: ตามโมเดล 4 บาน วัสดุบานยังไม่ระบุ (ไม้/อลูมิเนียม/เมลามีน)
A22: บานพับถ้วย/บานพับบานตู้ | B22: 8 | C22: ตัว | E22: ค่าสมมติ 2 ตัวต่อบาน
A23: มือจับบานตู้ใต้ซิงค์ (แท่งยาว 0.13 ม. ในโมเดล) | B23: 4 | C23: ชุด | E23: ค่าสมมติ 1 ต่อบาน
A25: เคาน์เตอร์ครัว (ก่อปูน ปูกระเบื้อง) | B25: กว้าง/สูง (ม.) | C25: ยาว (ม.) | D25: พื้นที่ (ตร.ม.) | E25: หมายเหตุ
A26: ท็อปเคาน์เตอร์ปูกระเบื้องสีดำ | B26: 0.72 | C26: 2.32 | D26: =B26*C26 | E26: 0.72x2.32 ม. (โครงเคาน์เตอร์ปูนอยู่ในงานก่อ)
A27: หน้าเคาน์เตอร์ปูกระเบื้องสีขาว | B27: 0.75 | C27: 2.32 | D27: =B27*C27 | E27: หน้าสูง 0.75 ม. ยาว 2.32 ม.
A28: รวมพื้นที่กระเบื้องเคาน์เตอร์ | D28: =D26+D27 | E28: ยังไม่หักช่องซิงค์ และไม่ระบุขนาดกระเบื้องจริง
A30: ข้อสมมติ (กระเบื้องเคาน์เตอร์) | B30: ค่า | E30: หมายเหตุ
A31: เผื่อเสียกระเบื้องเคาน์เตอร์ (เศษตัด) | B31: 0.15 | E31: พื้นที่เล็ก เผื่อสูงกว่า
A32: ปูนกาว (กก./ตร.ม.) | B32: 5
A33: ขนาดถุงปูนกาว (กก.) | B33: 20
A34: ยาแนว (กก./ตร.ม.) | B34: 0.4
A35: ขนาดถุงยาแนว (กก.) | B35: 1
A38: สิ่งที่ต้องซื้อ (จากชีตนี้)
A39: รายการที่ต้องซื้อ | B39: จำนวน | C39: หน่วย | D39: หมายเหตุ
A40: =A5 | B40: =D5 | C40: ชุด | D40: 0.75x0.41x0.84 ม. ยังไม่ระบุรุ่น
A41: =A6 | B41: =D6 | C41: ชุด | D41: 0.40x0.40 ม. (เคาน์เตอร์ปูนอยู่ในงานก่อ)
A42: =A7 | B42: =D7 | C42: ชุด | D42: สูง 0.31 ม.
A43: =A8 | B43: =D8 | C43: ชุด | D43: ค่าสมมติ 1 ชุดต่ออ่าง
A44: =A9 | B44: =D9 | C44: ชุด | D44: ค่าสมมติ 2 เส้นต่อห้อง (อ่าง 1 โถ 1)
A45: =A10 | B45: =D10 | C45: ชุด | D45: ท่อน้ำดีและวาล์วฉีดชำระอยู่ในชีตประปาแล้ว
A46: =A11 | B46: =D11 | C46: ชุด | D46: 0.42x0.20x0.92 ม. ในโมเดล
...

Sheet ฝ้าเพดาน
A1: ฝ้าเพดาน (พื้นที่ฝ้าจากโมเดล v413)
A3: รายการ | B3: พื้นที่ (ตร.ม.) | C3: ระดับฝ้า (ม.) | D3: หมายเหตุ
A4: ฝ้าในบ้าน (ห้องนอน ห้องน้ำ นั่งเล่น เก็บของ) | B4: 106.18 | C4: 3.49 | D4: พื้นที่เรียบแผ่นเดียวตามแนวผนัง (ไม่หักช่องเปิด)
A5: ฝ้าลอนลายไม้ (WPC หรือเมทัลชีท) ลานหน้าบ้าน | B5: 36.4 | C5: 3.39 | D5: พื้นที่แนวราบ 4.03×9.04 ม. ยาวถึงผนังห้องนอน 1 ลอนวางขวางแนวตะวันออก-ตะวันตก (ผิวลอนตามโมเดล ≈37.3 ตร.ม.) ไฟหลุม 6 ดวง
A6: ฝ้าลานตะวันออกเฉียงเหนือ (C3 P3 C9 C10) | B6: 8.65 | C6: 3.49 | D6: เพิ่มใหม่ 1.73×5.00 ม. หยุดที่ x = 12.73
A7: ฝ้าลานตะวันออกเฉียงใต้ (C11 C12 C14 P4) | B7: 6.05 | C7: 3.49 | D7: เพิ่มใหม่ 1.73×3.50 ม. หยุดที่ x = 12.73
A8: รวม | B8: =SUM(B4:B7)
A10: ยังไม่ระบุวัสดุฝ้า โครงคร่าว และสี ต้องกำหนดก่อนประเมินราคา ปริมาณนี้ไม่รวมเสา คาน และส่วนเผื่อเสีย
A13: สิ่งที่ต้องซื้อ (จากชีตนี้)
A14: เผื่อเสียแผ่นฝ้า | B14: 0.1 | D14: ค่าสมมติ
A15: รายการที่ต้องซื้อ | B15: จำนวน | C15: หน่วย | D15: หมายเหตุ
A16: แผ่นฝ้าเพดานเรียบ (วัสดุยังไม่ระบุ) รวมเผื่อเสีย ไม่รวมฝ้าลอนลายไม้ลานหน้าบ้าน | B16: =(B8-B5)*(1+$B$14) | C16: ตร.ม. | D16: ฝ้าในบ้าน + ลานตะวันออกเฉียงเหนือ/ใต้ (ไม่รวมแถวฝ้าลอนลายไม้)
A17: โครงฝ้าเพดาน (โครงคร่าว) ตามพื้นที่ฝ้า | B17: =B8 | C17: ตร.ม. | D17: โครงคร่าวตามพื้นที่ฝ้าทั้งหมด (ฝ้าลอนลายไม้อาจต้องใช้โครงเหล็กกล่อง/ระยะคร่าวตามผู้ผลิต)
A18: สกรู เทปปิดรอยต่อ เกร็ดฉาบรอยต่อ สีทาฝ้า | C18: เหมา
A19: ฝ้าลอนลายไม้ (WPC/เมทัลชีท) ลานหน้าบ้าน รวมเผื่อเสีย | B19: =B5*(1+$B$14) | C19: ตร.ม. | D19: เลือกชนิด/ความกว้างลอนก่อนแปลงเป็นแผ่นหรือเมตร ซื้อพร้อมเส้นเฟรม/ปิดขอบตามผู้ผลิต
